Workbook

Sheet Cover
A1: Income Expense Forecast
A25: Your Personal Finance Organizer

Sheet April 2026 - June 2026
A1: Income Expense For the Forecast Year 2026 April - June 2026
A3: Assets | B3: Banks ~ HSBC Bank ~ Bank Of China ~ Standard Chartered Bank | C3: 41.51
B4: Coins And Cash | C4: 724.7
B5: Unit Trusts ~ AIA Insurance ~ MPF | C5: 0
B6: Alipay HK | C6: 0
B7: Paypal | C7: 9
B8: Octopus Remain Value | C8: 31.7
B9: Total Asset | C9: =SUM(C3:C8) -> 806.91
A11: April 20th - May 19th 2026 Revenue / Defered Debts Or Expenses
A12: Date | B12: Name | C12: Description | E12: Amount
A13: 20th April 2026 | B13: Social Welfare | C13: Disability Allowance | E13: 2485
A14: 20th April 2026 | B14: Communication | C14: China Mobile | E14: 12
B15: e-cigarette | C15: Already Brought E-cigarette on March enough for this month | E15: 900
B16: Optifast plus | C16: Sell it | E16: 1050
B17: Loan | C17: Borrow from Lawrence | E17: 700
A18: 46138 | B18: Mother | C18: 1. Return back From Mom HKT Fixed Line Services - $140 2. Remaining Mother Credit Card to puchase from Amazon - $7.6 3. Borrow $40 | E18: 187.6
B19: Communication | C19: Netflix Not Yet Registered | E19: 118
A20: 21st April 2026 | B20: Octopus | C20: Topup $50 For Octopus | E20: 50
D21: Forecast Total | E21: =SUM(E13:E20) -> 5502.6
A23: May 20th - June 17th 2026 Revenue / Defered Debts Or Expenses
A24: Date | B24: Name | C24: Description | E24: Amount
A25: 20th May 2026 | B25: Social Welfare | C25: Disability Allowance | E25: 2485
A26: Early June 2026 | B26: Social Welfare | C26: Additional One Month Disability Allowance | E26: 2140
B27: Mother | C27: 1. 20th May 2026 - Give back the Water Fees paid for the government. - $112.3 2. 23rd May 2026 - Mother payback for the shopping. - $100 3. 17th June 2026 - Mother payback for the OK Store - $15 | E27: 227.3
A28: 20th May 2026 | B28: e-cigarette | C28: Buy 5 give 1 discount for $695 original $900 | E28: 205
B29: Octopus | C29: 1. Topup For Octopus Card (Credit $50). 2. Topup For Octopus Card (Credit $50) on 23/05. 3. Topup For Octopus Card (Credit $50) on 01/06. | E29: 150
D30: Forecast Total | E30: =SUM(E25:E29) -> 5207.3
A32: June 18th - August 19th 2026 Revenue / Defered Debts Or Expenses
A33: Date | B33: Name | C33: Description | E33: Amount
A34: 20th June 2026 | B34: Social Welfare | C34: Disability Allowance | E34: 2485
B35: Communication | C35: Cancel Netflix | E35: 118
B36: Mother | C36: 1. Payback For Clothes Washing Detergent. 2. Borrow $100 from Mom. | E36: 170
B37: Lawrence | C37: 1. $300 Rent my Luggage. 2. Borrow $500 from Lawrece. | E37: 800
B38: Octopus | C38: 1. Topup For Octopus Card (Credit $100). 2. Topup For Octopus Card (Credit $100) 19/07. | E38: 200
D39: Forecast Total | E39: =SUM(E34:E38) -> 3773
A41: Fixed Expense For the Year 2026 April - June 2026
A42: Name | B42: Description | C42: Amount
A43: Mobile And Communications
A44: China Mobile | B44: Broadband | C44: 78
A45: Netflix | B45: Premium | C45: 118
...

Sheet July 2026- September 2026
A1: Income Expense For the Forecast Year 2026 July - September 2026
A3: Assets | B3: Banks ~ HSBC Bank ~ Bank Of China ~ Standard Chartered Bank | C3: ='April 2026 - June 2026'!C3 -> 41.51
B4: Coins And Cash | C4: ='April 2026 - June 2026'!C4 -> 724.7
B5: Unit Trusts ~ AIA Insurance ~ MPF | C5: ='April 2026 - June 2026'!C5 -> 0
B6: Alipay HK | C6: ='April 2026 - June 2026'!C6 -> 0
B7: Paypal | C7: 9
B8: Octopus Remain Value | C8: ='April 2026 - June 2026'!C8 -> 31.7
B9: Total Asset | C9: ='April 2026 - June 2026'!C9 -> 806.91
A11: July 20th - August 19th 2026 Revenue / Defered Debts Or Expenses
A12: Date | B12: Name | C12: Description | E12: Amount
A13: 20th July 2026 | B13: Social Welfare | C13: Disability Allowance | E13: 2485
A14: 21st July 2026 | B14: Hair Cut | C14: Cancel hair cut for this current month. | E14: 55
A15: 06th Aug 2026 | B15: Mother | C15: 1. Borrow $100 2. Use Mother Credit Card for shopping HKTVmall. $670.4 | E15: 770.4
D16: Forecast Total | E16: =SUM(E13:E15) -> 3310.4
A18: August 20th - September 17th 2026 Revenue / Defered Debts Or Expenses
A19: Date | B19: Name | C19: Description | E19: Amount
A20: 20th August 2026 | B20: Social Welfare | C20: Disability Allowance | E20: 2485
A21: 20th August 2026 | B21: Octopus | C21: 1. Top up $50 for Octopus 2. Top up $50 for Octopus 03/09 | E21: 100
A22: 23rd August 2026 | B22: Alipay | C22: A discount of $3.08 for iHerb payment | E22: 3.08
A23: 2nd September 2026 | B23: Mother | C23: 1. Borrow $60 2. Payback Water bill through Alipay $74.1. 3. Borrow $100 ~ 16/09 | E23: 234.1
A24: 3rd September 2026 | B24: Brother | C24: 1. A gift for birthday $1000 from Lawrence 2. Borrow $500 | E24: 1500
D25: Forecast Total | E25: =SUM(E20:E24) -> 4322.18
A27: September 18th - October 19th 2026 Revenue / Defered Debts Or Expenses
A28: Date | B28: Name | C28: Description | E28: Amount
A29: 18th September 2026 | B29: Social Welfare | C29: Disability Allowance | E29: 2485
A30: 18th September 2026 | B30: Octopus | C30: 1. Top up $50 for Octopus 18/09 2. Top up $50 for Octopus 18/09 3. Top up $50 for Octopus 26/09 | E30: 150
A31: 21st September 2026 | B31: Mother | C31: 1. A gift for birthday $500 from Mother. 2. Refund from "GoDaddy domain" to moms credit card account. 27/09/2025 - $193.98 3. Refund from "GoDaddy domain" to moms credit card account. 29/09/2025 - $721.86 | E31: 1415.84
D32: Forecast Total | E32: =SUM(E29:E31) -> 4050.84
A34: Fixed Expense For the Year 2026 July - September 2026
A35: Name | B35: Description | C35: Amount
A36: Mobile And Communications
A37: China Mobile | B37: Broadband | C37: 78
A38: Netflix | B38: Premium | C38: 0
A39: China Mobile | B39: 5G Plan | C39: 138
B40: Total Payment | C40: =SUM(C37:C39) -> 216
A41: Credit Card Installments/Expense
A43: Citi Bank | C43: 0
A44: SC Bank - Smart | C44: 0
A45: Bank Of China | C45: 0
A46: HSBC Red | C46: 0
...

Sheet October 2026- December 2026
A1: Income Expense For the Forecast Year 2026 October - December 2026
A3: Assets | B3: Banks ~ HSBC Bank ~ Bank Of China ~ Standard Chartered Bank | C3: ='April 2026 - June 2026'!C3 -> 41.51
B4: Coins And Cash | C4: ='April 2026 - June 2026'!C4 -> 724.7
B5: Unit Trusts ~ AIA Insurance ~ MPF | C5: ='April 2026 - June 2026'!C5 -> 0
B6: Alipay HK | C6: ='April 2026 - June 2026'!C6 -> 0
B7: Paypal | C7: 9
B8: Octopus Remain Value | C8: ='April 2026 - June 2026'!C8 -> 31.7
B9: Total Asset | C9: ='April 2026 - June 2026'!C9 -> 806.91
A11: October 20th - November 19th 2026 Revenue / Defered Debts Or Expenses
A12: Date | B12: Name | C12: Description | E12: Amount
A13: 20th October 2026 | B13: Social Welfare | C13: Disability Allowance | E13: 2485
A14: 20th October 2026 | C14: 1. Cancel hair cut. | E14: 55
A15: 20th October 2026 | B15: Mother | C15: 1. Payback $136 for the fixed line fees | E15: 136
A16: 20th October 2026 | B16: Octopus | C16: 1. Top up $100 for Octopus | E16: 100
A17: 20th October 2026 | B17: Carousel | C17: Cancel carousel order for dyeing | E17: 54.72
D18: Forecast Total | E18: =SUM(E13:E17) -> 2830.72
A20: November 20th - December 17th 2026 Revenue / Defered Debts Or Expenses
A21: Date | B21: Name | C21: Description | E21: Amount
A22: 20th November 2026 | B22: Social Welfare | C22: Disability Allowance | E22: 2485
E23: 0
D24: Forecast Total | E24: =SUM(E22:E23) -> 2485
A26: December 18th - January 19th 2027 Revenue / Defered Debts Or Expenses
A27: Date | B27: Name | C27: Description | E27: Amount
A28: 18th December 2026 | B28: Social Welfare | C28: Disability Allowance | E28: 2485
E29: 0
D30: Forecast Total | E30: =SUM(E28:E29) -> 2485
A32: Fixed Expense For the Year 2026 October - December 2026
A33: Name | B33: Description | C33: Amount
A34: Mobile And Communications
A35: China Mobile | B35: Broadband | C35: 78
A36: Netflix | B36: Premium | C36: 0
A37: China Mobile | B37: 5G Plan | C37: 138
B38: Total Payment | C38: =SUM(C35:C37) -> 216
A39: Credit Card Installments/Expense
A41: Citi Bank | C41: 0
A42: SC Bank - Smart | C42: 0
A43: Bank Of China | C43: 0
A44: HSBC Red | C44: 0
B45: Total Installments | C45: =SUM(C41:C44) -> 0
A46: Donation
...
